Workbook

Sheet G7 Input
A1: Ccy Pair | B1: Mid | C1: ATM | D1: 25D RR | E1: 10D RR | F1: 25D BF | G1: 10D BF | I1: Spread | J1: ATM | K1: 25D RR | L1: 10D RR | M1: 25D BF | N1: 10D BF | P1: BID | Q1: ATM | R1: 25D RR | S1: 10D RR | T1: 25D BF | U1: 10D BF | W1: OFFER | X1: ATM | Y1: 25D RR | Z1: 10D RR | AA1: 25D BF | AB1: 10D BF
A2: AUDUSD | B2: ON | C2: =[1]AUDUSD!$B15 -> 0.0644 | D2: =[1]AUDUSD!$F15 -> -0.0033 | E2: =[1]AUDUSD!$E15 -> -0.0064 | F2: =[1]AUDUSD!$D15 -> 0.001 | G2: =[1]AUDUSD!$C15 -> 0.0034 | I2: ON | J2: =[2]G7!$C2 -> 0.8 | K2: 1.2 | L2: 2.4 | M2: 1.2 | N2: 2.4 | P2: ON | Q2: =(C2-J2/200)-0.002 -> 0.0584 | R2: =D2-K2/200 -> -0.0093 | S2: =E2-L2/200 -> -0.0184 | T2: =F2-M2/200 -> -0.005 | U2: =G2-N2/200 -> -0.0086 | W2: ON | X2: =(C2+J2/200)-0.002 -> 0.0664 | Y2: =D2+K2/200 -> 0.0027 | Z2: =E2+L2/200 -> 0.0056 | AA2: =F2+M2/200 -> 0.007 | AB2: =G2+N2/200 -> 0.0154
A3: AUDUSD | B3: 1W | C3: =[1]AUDUSD!$B16 -> 0.0625 | D3: =[1]AUDUSD!$F16 -> -0.0036 | E3: =[1]AUDUSD!$E16 -> -0.0081 | F3: =[1]AUDUSD!$D16 -> 0.0012 | G3: =[1]AUDUSD!$C16 -> 0.0043 | I3: 1W | J3: =[2]G7!$C3 -> 0.68 | K3: 0.5 | L3: 1 | M3: 0.5 | N3: 1 | P3: 1W | Q3: =(C3-J3/200)-0.002 -> 0.0571 | R3: =D3-K3/200 -> -0.0061 | S3: =E3-L3/200 -> -0.0131 | T3: =F3-M3/200 -> -0.0013 | U3: =G3-N3/200 -> -0.0007 | W3: 1W | X3: =(C3+J3/200)-0.002 -> 0.0639 | Y3: =D3+K3/200 -> -0.0011 | Z3: =E3+L3/200 -> -0.0031 | AA3: =F3+M3/200 -> 0.0037 | AB3: =G3+N3/200 -> 0.0093
A4: AUDUSD | B4: 2W | C4: =[1]AUDUSD!$B17 -> 0.0669 | D4: =[1]AUDUSD!$F17 -> -0.0041 | E4: =[1]AUDUSD!$E17 -> -0.009 | F4: =[1]AUDUSD!$D17 -> 0.0013 | G4: =[1]AUDUSD!$C17 -> 0.0047 | I4: 2W | J4: =[2]G7!$C4 -> 0.53 | K4: 0.3 | L4: 0.6 | M4: 0.3 | N4: 0.6 | P4: 2W | Q4: =(C4-J4/200)-0.002 -> 0.06225 | R4: =D4-K4/200 -> -0.0056 | S4: =E4-L4/200 -> -0.012 | T4: =F4-M4/200 -> -0.0002 | U4: =G4-N4/200 -> 0.0017 | W4: 2W | X4: =(C4+J4/200)-0.002 -> 0.06755 | Y4: =D4+K4/200 -> -0.0026 | Z4: =E4+L4/200 -> -0.006 | AA4: =F4+M4/200 -> 0.0028 | AB4: =G4+N4/200 -> 0.0077
A5: AUDUSD | B5: 1M | C5: =[1]AUDUSD!$B18 -> 0.07 | D5: =[1]AUDUSD!$F18 -> -0.0049 | E5: =[1]AUDUSD!$E18 -> -0.01 | F5: =[1]AUDUSD!$D18 -> 0.0014 | G5: =[1]AUDUSD!$C18 -> 0.0051 | I5: 1M | J5: =[2]G7!$C5 -> 0.34 | K5: 0.2 | L5: 0.4 | M5: 0.2 | N5: 0.4 | P5: 1M | Q5: =(C5-J5/200)-0.002 -> 0.0663 | R5: =D5-K5/200 -> -0.0059 | S5: =E5-L5/200 -> -0.012 | T5: =F5-M5/200 -> 0.0004 | U5: =G5-N5/200 -> 0.0031 | W5: 1M | X5: =(C5+J5/200)-0.002 -> 0.0697 | Y5: =D5+K5/200 -> -0.0039 | Z5: =E5+L5/200 -> -0.008 | AA5: =F5+M5/200 -> 0.0024 | AB5: =G5+N5/200 -> 0.0071
A6: AUDUSD | B6: 2M | C6: =[1]AUDUSD!$B19 -> 0.0724 | D6: =[1]AUDUSD!$F19 -> -0.0056 | E6: =[1]AUDUSD!$E19 -> -0.0117 | F6: =[1]AUDUSD!$D19 -> 0.0017 | G6: =[1]AUDUSD!$C19 -> 0.006 | I6: 2M | J6: =[2]G7!$C6 -> 0.34 | K6: 0.2 | L6: 0.4 | M6: 0.2 | N6: 0.4 | P6: 2M | Q6: =(C6-J6/200)-0.002 -> 0.0687 | R6: =D6-K6/200 -> -0.0066 | S6: =E6-L6/200 -> -0.0137 | T6: =F6-M6/200 -> 0.0007 | U6: =G6-N6/200 -> 0.004 | W6: 2M | X6: =(C6+J6/200)-0.002 -> 0.0721 | Y6: =D6+K6/200 -> -0.0046 | Z6: =E6+L6/200 -> -0.0097 | AA6: =F6+M6/200 -> 0.0027 | AB6: =G6+N6/200 -> 0.008
A7: AUDUSD | B7: 3M | C7: =[1]AUDUSD!$B20 -> 0.074 | D7: =[1]AUDUSD!$F20 -> -0.0062 | E7: =[1]AUDUSD!$E20 -> -0.0132 | F7: =[1]AUDUSD!$D20 -> 0.002 | G7: =[1]AUDUSD!$C20 -> 0.0069 | I7: 3M | J7: =[2]G7!$C7 -> 0.34 | K7: 0.2 | L7: 0.4 | M7: 0.2 | N7: 0.4 | P7: 3M | Q7: =(C7-J7/200)-0.002 -> 0.0703 | R7: =D7-K7/200 -> -0.0072 | S7: =E7-L7/200 -> -0.0152 | T7: =F7-M7/200 -> 0.001 | U7: =G7-N7/200 -> 0.0049 | W7: 3M | X7: =(C7+J7/200)-0.002 -> 0.0737 | Y7: =D7+K7/200 -> -0.0052 | Z7: =E7+L7/200 -> -0.0112 | AA7: =F7+M7/200 -> 0.003 | AB7: =G7+N7/200 -> 0.0089
A8: AUDUSD | B8: 6M | C8: =[1]AUDUSD!$B21 -> 0.0775 | D8: =[1]AUDUSD!$F21 -> -0.0075 | E8: =[1]AUDUSD!$E21 -> -0.0159 | F8: =[1]AUDUSD!$D21 -> 0.0022 | G8: =[1]AUDUSD!$C21 -> 0.0077 | I8: 6M | J8: =[2]G7!$C8 -> 0.33 | K8: 0.2 | L8: 0.4 | M8: 0.2 | N8: 0.4 | P8: 6M | Q8: =(C8-J8/200)-0.002 -> 0.07385 | R8: =D8-K8/200 -> -0.0085 | S8: =E8-L8/200 -> -0.0179 | T8: =F8-M8/200 -> 0.0012 | U8: =G8-N8/200 -> 0.0057 | W8: 6M | X8: =(C8+J8/200)-0.002 -> 0.07715 | Y8: =D8+K8/200 -> -0.0065 | Z8: =E8+L8/200 -> -0.0139 | AA8: =F8+M8/200 -> 0.0032 | AB8: =G8+N8/200 -> 0.0097
A9: AUDUSD | B9: 9M | C9: =[1]AUDUSD!$B22 -> 0.0811 | D9: =[1]AUDUSD!$F22 -> -0.0085 | E9: =[1]AUDUSD!$E22 -> -0.0181 | F9: =[1]AUDUSD!$D22 -> 0.0025 | G9: =[1]AUDUSD!$C22 -> 0.009 | I9: 9M | J9: =[2]G7!$C9 -> 0.33 | K9: 0.2 | L9: 0.4 | M9: 0.2 | N9: 0.4 | P9: 9M | Q9: =(C9-J9/200)-0.002 -> 0.07745 | R9: =D9-K9/200 -> -0.0095 | S9: =E9-L9/200 -> -0.0201 | T9: =F9-M9/200 -> 0.0015 | U9: =G9-N9/200 -> 0.007 | W9: 9M | X9: =(C9+J9/200)-0.002 -> 0.08075 | Y9: =D9+K9/200 -> -0.0075 | Z9: =E9+L9/200 -> -0.0161 | AA9: =F9+M9/200 -> 0.0035 | AB9: =G9+N9/200 -> 0.011
A10: AUDUSD | B10: 1Y | C10: =[1]AUDUSD!$B23 -> 0.0842 | D10: =[1]AUDUSD!$F23 -> -0.0095 | E10: =[1]AUDUSD!$E23 -> -0.0202 | F10: =[1]AUDUSD!$D23 -> 0.0029 | G10: =[1]AUDUSD!$C23 -> 0.0103 | I10: 1Y | J10: =[2]G7!$C10 -> 0.35 | K10: 0.2 | L10: 0.4 | M10: 0.2 | N10: 0.4 | P10: 1Y | Q10: =(C10-J10/200)-0.002 -> 0.08045 | R10: =D10-K10/200 -> -0.0105 | S10: =E10-L10/200 -> -0.0222 | T10: =F10-M10/200 -> 0.0019 | U10: =G10-N10/200 -> 0.0083 | W10: 1Y | X10: =(C10+J10/200)-0.002 -> 0.08395 | Y10: =D10+K10/200 -> -0.0085 | Z10: =E10+L10/200 -> -0.0182 | AA10: =F10+M10/200 -> 0.0039 | AB10: =G10+N10/200 -> 0.0123
A11: AUDUSD | B11: 2Y | C11: =[1]AUDUSD!$B24 -> 0.0885 | D11: =[1]AUDUSD!$F24 -> -0.0117 | E11: =[1]AUDUSD!$E24 -> -0.0243 | F11: =[1]AUDUSD!$D24 -> 0.0039 | G11: =[1]AUDUSD!$C24 -> 0.0132 | I11: 2Y | J11: =[2]G7!$C11 -> 0.4 | K11: 0.2 | L11: 0.4 | M11: 0.2 | N11: 0.4 | P11: 2Y | Q11: =(C11-J11/200)-0.002 -> 0.0845 | R11: =D11-K11/200 -> -0.0127 | S11: =E11-L11/200 -> -0.0263 | T11: =F11-M11/200 -> 0.0029 | U11: =G11-N11/200 -> 0.0112 | W11: 2Y | X11: =(C11+J11/200)-0.002 -> 0.0885 | Y11: =D11+K11/200 -> -0.0107 | Z11: =E11+L11/200 -> -0.0223 | AA11: =F11+M11/200 -> 0.0049 | AB11: =G11+N11/200 -> 0.0152
A12: AUDUSD | B12: 3Y | C12: =[1]AUDUSD!$B25 -> 0.0901 | D12: =[1]AUDUSD!$F25 -> -0.012 | E12: =[1]AUDUSD!$E25 -> -0.0248 | F12: =[1]AUDUSD!$D25 -> 0.0038 | G12: =[1]AUDUSD!$C25 -> 0.0133 | I12: 3Y | J12: =[2]G7!$C12 -> 0.47 | K12: 0.2 | L12: 0.4 | M12: 0.2 | N12: 0.4 | P12: 3Y | Q12: =(C12-J12/200)-0.002 -> 0.08575 | R12: =D12-K12/200 -> -0.013 | S12: =E12-L12/200 -> -0.0268 | T12: =F12-M12/200 -> 0.0028 | U12: =G12-N12/200 -> 0.0113 | W12: 3Y | X12: =(C12+J12/200)-0.002 -> 0.09045 | Y12: =D12+K12/200 -> -0.011 | Z12: =E12+L12/200 -> -0.0228 | AA12: =F12+M12/200 -> 0.0048 | AB12: =G12+N12/200 -> 0.0153
A15: Ccy Pair | B15: Mid | C15: ATM | D15: 25D RR | E15: 10D RR | F15: 25D BF | G15: 10D BF | I15: Spread | J15: ATM | K15: 25D RR | L15: 10D RR | M15: 25D BF | N15: 10D BF | P15: BID | Q15: ATM | R15: 25D RR | S15: 10D RR | T15: 25D BF | U15: 10D BF | W15: OFFER | X15: ATM | Y15: 25D RR | Z15: 10D RR | AA15: 25D BF | AB15: 10D BF
A16: AUDHKD | B16: ON | C16: =[1]AUDHKD!$B15 -> 0.0631 | D16: =[1]AUDHKD!$F15 -> -0.0039 | E16: =[1]AUDHKD!$E15 -> -0.0077 | F16: =[1]AUDHKD!$D15 -> 0.0012 | G16: =[1]AUDHKD!$C15 -> 0.0043 | I16: ON | J16: =[2]G7!$D2 -> 3.1 | K16: 1.2 | L16: 2.4 | M16: 1.2 | N16: 2.4 | P16: ON | Q16: =(C16-J16/200)-0.002 -> 0.0456 | R16: =D16-K16/200 -> -0.0099 | S16: =E16-L16/200 -> -0.0197 | T16: =F16-M16/200 -> -0.0048 | U16: =G16-N16/200 -> -0.0077 | W16: ON | X16: =(C16+J16/200)-0.002 -> 0.0766 | Y16: =D16+K16/200 -> 0.0021 | Z16: =E16+L16/200 -> 0.0043 | AA16: =F16+M16/200 -> 0.0072 | AB16: =G16+N16/200 -> 0.0163
A17: AUDHKD | B17: 1W | C17: =[1]AUDHKD!$B16 -> 0.0618 | D17: =[1]AUDHKD!$F16 -> -0.0039 | E17: =[1]AUDHKD!$E16 -> -0.0075 | F17: =[1]AUDHKD!$D16 -> 0.0011 | G17: =[1]AUDHKD!$C16 -> 0.0042 | I17: 1W | J17: =[2]G7!$D3 -> 2.11 | K17: 0.5 | L17: 1 | M17: 0.5 | N17: 1 | P17: 1W | Q17: =(C17-J17/200)-0.002 -> 0.04925 | R17: =D17-K17/200 -> -0.0064 | S17: =E17-L17/200 -> -0.0125 | T17: =F17-M17/200 -> -0.0014 | U17: =G17-N17/200 -> -0.0008 | W17: 1W | X17: =(C17+J17/200)-0.002 -> 0.07035 | Y17: =D17+K17/200 -> -0.0014 | Z17: =E17+L17/200 -> -0.0025 | AA17: =F17+M17/200 -> 0.0036 | AB17: =G17+N17/200 -> 0.0092
A18: AUDHKD | B18: 2W | C18: =[1]AUDHKD!$B17 -> 0.0677 | D18: =[1]AUDHKD!$F17 -> -0.0047 | E18: =[1]AUDHKD!$E17 -> -0.0091 | F18: =[1]AUDHKD!$D17 -> 0.0013 | G18: =[1]AUDHKD!$C17 -> 0.0048 | I18: 2W | J18: =[2]G7!$D4 -> 1.51 | K18: 0.3 | L18: 0.6 | M18: 0.3 | N18: 0.6 | P18: 2W | Q18: =(C18-J18/200)-0.002 -> 0.05815 | R18: =D18-K18/200 -> -0.0062 | S18: =E18-L18/200 -> -0.0121 | T18: =F18-M18/200 -> -0.0002 | U18: =G18-N18/200 -> 0.0018 | W18: 2W | X18: =(C18+J18/200)-0.002 -> 0.07325 | Y18: =D18+K18/200 -> -0.0032 | Z18: =E18+L18/200 -> -0.0061 | AA18: =F18+M18/200 -> 0.0028 | AB18: =G18+N18/200 -> 0.0078
A19: AUDHKD | B19: 1M | C19: =[1]AUDHKD!$B18 -> 0.0694 | D19: =[1]AUDHKD!$F18 -> -0.005 | E19: =[1]AUDHKD!$E18 -> -0.0097 | F19: =[1]AUDHKD!$D18 -> 0.0014 | G19: =[1]AUDHKD!$C18 -> 0.005 | I19: 1M | J19: =[2]G7!$D5 -> 0.75 | K19: 0.2 | L19: 0.4 | M19: 0.2 | N19: 0.4 | P19: 1M | Q19: =(C19-J19/200)-0.002 -> 0.06365 | R19: =D19-K19/200 -> -0.006 | S19: =E19-L19/200 -> -0.0117 | T19: =F19-M19/200 -> 0.0004 | U19: =G19-N19/200 -> 0.003 | W19: 1M | X19: =(C19+J19/200)-0.002 -> 0.07115 | Y19: =D19+K19/200 -> -0.004 | Z19: =E19+L19/200 -> -0.0077 | AA19: =F19+M19/200 -> 0.0024 | AB19: =G19+N19/200 -> 0.007
A20: AUDHKD | B20: 2M | C20: =[1]AUDHKD!$B19 -> 0.0723 | D20: =[1]AUDHKD!$F19 -> -0.0058 | E20: =[1]AUDHKD!$E19 -> -0.0113 | F20: =[1]AUDHKD!$D19 -> 0.0016 | G20: =[1]AUDHKD!$C19 -> 0.006 | I20: 2M | J20: =[2]G7!$D6 -> 0.74 | K20: 0.2 | L20: 0.4 | M20: 0.2 | N20: 0.4 | P20: 2M | Q20: =(C20-J20/200)-0.002 -> 0.0666 | R20: =D20-K20/200 -> -0.0068 | S20: =E20-L20/200 -> -0.0133 | T20: =F20-M20/200 -> 0.0006 | U20: =G20-N20/200 -> 0.004 | W20: 2M | X20: =(C20+J20/200)-0.002 -> 0.074 | Y20: =D20+K20/200 -> -0.0048 | Z20: =E20+L20/200 -> -0.0093 | AA20: =F20+M20/200 -> 0.0026 | AB20: =G20+N20/200 -> 0.008
A21: AUDHKD | B21: 3M | C21: =[1]AUDHKD!$B20 -> 0.0739 | D21: =[1]AUDHKD!$F20 -> -0.0065 | E21: =[1]AUDHKD!$E20 -> -0.0126 | F21: =[1]AUDHKD!$D20 -> 0.0018 | G21: =[1]AUDHKD!$C20 -> 0.0068 | I21: 3M | J21: =[2]G7!$D7 -> 0.75 | K21: 0.2 | L21: 0.4 | M21: 0.2 | N21: 0.4 | P21: 3M | Q21: =(C21-J21/200)-0.002 -> 0.06815 | R21: =D21-K21/200 -> -0.0075 | S21: =E21-L21/200 -> -0.0146 | T21: =F21-M21/200 -> 0.0008 | U21: =G21-N21/200 -> 0.0048 | W21: 3M | X21: =(C21+J21/200)-0.002 -> 0.07565 | Y21: =D21+K21/200 -> -0.0055 | Z21: =E21+L21/200 -> -0.0106 | AA21: =F21+M21/200 -> 0.0028 | AB21: =G21+N21/200 -> 0.0088
A22: AUDHKD | B22: 6M | C22: =[1]AUDHKD!$B21 -> 0.0774 | D22: =[1]AUDHKD!$F21 -> -0.0077 | E22: =[1]AUDHKD!$E21 -> -0.0149 | F22: =[1]AUDHKD!$D21 -> 0.0019 | G22: =[1]AUDHKD!$C21 -> 0.0076 | I22: 6M | J22: =[2]G7!$D8 -> 0.7 | K22: 0.2 | L22: 0.4 | M22: 0.2 | N22: 0.4 | P22: 6M | Q22: =(C22-J22/200)-0.002 -> 0.0719 | R22: =D22-K22/200 -> -0.0087 | S22: =E22-L22/200 -> -0.0169 | T22: =F22-M22/200 -> 0.0009 | U22: =G22-N22/200 -> 0.0056 | W22: 6M | X22: =(C22+J22/200)-0.002 -> 0.0789 | Y22: =D22+K22/200 -> -0.0067 | Z22: =E22+L22/200 -> -0.0129 | AA22: =F22+M22/200 -> 0.0029 | AB22: =G22+N22/200 -> 0.0096
A23: AUDHKD | B23: 9M | C23: =[1]AUDHKD!$B22 -> 0.0819 | D23: =[1]AUDHKD!$F22 -> -0.0094 | E23: =[1]AUDHKD!$E22 -> -0.018 | F23: =[1]AUDHKD!$D22 -> 0.0023 | G23: =[1]AUDHKD!$C22 -> 0.0094 | I23: 9M | J23: =[2]G7!$D9 -> 0.7 | K23: 0.2 | L23: 0.4 | M23: 0.2 | N23: 0.4 | P23: 9M | Q23: =(C23-J23/200)-0.002 -> 0.0764 | R23: =D23-K23/200 -> -0.0104 | S23: =E23-L23/200 -> -0.02 | T23: =F23-M23/200 -> 0.0013 | U23: =G23-N23/200 -> 0.0074 | W23: 9M | X23: =(C23+J23/200)-0.002 -> 0.0834 | Y23: =D23+K23/200 -> -0.0084 | Z23: =E23+L23/200 -> -0.016 | AA23: =F23+M23/200 -> 0.0033 | AB23: =G23+N23/200 -> 0.0114
A24: AUDHKD | B24: 1Y | C24: =[1]AUDHKD!$B23 -> 0.0845 | D24: =[1]AUDHKD!$F23 -> -0.0102 | E24: =[1]AUDHKD!$E23 -> -0.0196 | F24: =[1]AUDHKD!$D23 -> 0.0025 | G24: =[1]AUDHKD!$C23 -> 0.0103 | I24: 1Y | J24: =[2]G7!$D10 -> 0.73 | K24: 0.2 | L24: 0.4 | M24: 0.2 | N24: 0.4 | P24: 1Y | Q24: =(C24-J24/200)-0.002 -> 0.07885 | R24: =D24-K24/200 -> -0.0112 | S24: =E24-L24/200 -> -0.0216 | T24: =F24-M24/200 -> 0.0015 | U24: =G24-N24/200 -> 0.0083 | W24: 1Y | X24: =(C24+J24/200)-0.002 -> 0.08615 | Y24: =D24+K24/200 -> -0.0092 | Z24: =E24+L24/200 -> -0.0176 | AA24: =F24+M24/200 -> 0.0035 | AB24: =G24+N24/200 -> 0.0123
A25: AUDHKD | B25: 2Y | C25: =[1]AUDHKD!$B24 -> 0.0891 | D25: =[1]AUDHKD!$F24 -> -0.0124 | E25: =[1]AUDHKD!$E24 -> -0.0235 | F25: =[1]AUDHKD!$D24 -> 0.0029 | G25: =[1]AUDHKD!$C24 -> 0.0124 | I25: 2Y | J25: =[2]G7!$D11 -> 1.01 | K25: 0.2 | L25: 0.4 | M25: 0.2 | N25: 0.4 | P25: 2Y | Q25: =(C25-J25/200)-0.002 -> 0.08205 | R25: =D25-K25/200 -> -0.0134 | S25: =E25-L25/200 -> -0.0255 | T25: =F25-M25/200 -> 0.0019 | U25: =G25-N25/200 -> 0.0104 | W25: 2Y | X25: =(C25+J25/200)-0.002 -> 0.09215 | Y25: =D25+K25/200 -> -0.0114 | Z25: =E25+L25/200 -> -0.0215 | AA25: =F25+M25/200 -> 0.0039 | AB25: =G25+N25/200 -> 0.0144
A26: AUDHKD | B26: 3Y | C26: =[1]AUDHKD!$B25 -> 0.0916 | D26: =[1]AUDHKD!$F25 -> -0.0131 | E26: =[1]AUDHKD!$E25 -> -0.0245 | F26: =[1]AUDHKD!$D25 -> 0.0027 | G26: =[1]AUDHKD!$C25 -> 0.0123 | I26: 3Y | J26: =[2]G7!$D12 -> 1.29 | K26: 0.2 | L26: 0.4 | M26: 0.2 | N26: 0.4 | P26: 3Y | Q26: =(C26-J26/200)-0.002 -> 0.08315 | R26: =D26-K26/200 -> -0.0141 | S26: =E26-L26/200 -> -0.0265 | T26: =F26-M26/200 -> 0.0017 | U26: =G26-N26/200 -> 0.0103 | W26: 3Y | X26: =(C26+J26/200)-0.002 -> 0.09605 | Y26: =D26+K26/200 -> -0.0121 | Z26: =E26+L26/200 -> -0.0225 | AA26: =F26+M26/200 -> 0.0037 | AB26: =G26+N26/200 -> 0.0143
A29: Ccy Pair | B29: Mid | C29: ATM | D29: 25D RR | E29: 10D RR | F29: 25D BF | G29: 10D BF | I29: Spread | J29: ATM | K29: 25D RR | L29: 10D RR | M29: 25D BF | N29: 10D BF | P29: BID | Q29: ATM | R29: 25D RR | S29: 10D RR | T29: 25D BF | U29: 10D BF | W29: OFFER | X29: ATM | Y29: 25D RR | Z29: 10D RR | AA29: 25D BF | AB29: 10D BF
A30: USDCAD | B30: ON | C30: =[1]USDCAD!$B15 -> 0.0536 | D30: =[1]USDCAD!$F15 -> 0.0003 | E30: =[1]USDCAD!$E15 -> 0.0006 | F30: =[1]USDCAD!$D15 -> 0.0009 | G30: =[1]USDCAD!$C15 -> 0.0031 | I30: ON | J30: =[2]G7!$C14 -> 2.64 | K30: 0.9 | L30: 1.8 | M30: 1.3 | N30: 2.6 | P30: ON | Q30: =(C30-J30/200)-0.002 -> 0.0384 | R30: =D30-K30/200 -> -0.0042 | S30: =E30-L30/200 -> -0.0084 | T30: =F30-M30/200 -> -0.0056 | U30: =G30-N30/200 -> -0.0099 | W30: ON | X30: =(C30+J30/200)-0.002 -> 0.0648 | Y30: =D30+K30/200 -> 0.0048 | Z30: =E30+L30/200 -> 0.0096 | AA30: =F30+M30/200 -> 0.0074 | AB30: =G30+N30/200 -> 0.0161
A31: USDCAD | B31: 1W | C31: =[1]USDCAD!$B16 -> 0.0492 | D31: =[1]USDCAD!$F16 -> 0.0003 | E31: =[1]USDCAD!$E16 -> 0.0006 | F31: =[1]USDCAD!$D16 -> 0.0012 | G31: =[1]USDCAD!$C16 -> 0.0036 | I31: 1W | J31: =[2]G7!$C15 -> 1.23 | K31: 0.4 | L31: 0.8 | M31: 0.4 | N31: 0.8 | P31: 1W | Q31: =(C31-J31/200)-0.002 -> 0.04105 | R31: =D31-K31/200 -> -0.0017 | S31: =E31-L31/200 -> -0.0034 | T31: =F31-M31/200 -> -0.0008 | U31: =G31-N31/200 -> -0.0004 | W31: 1W | X31: =(C31+J31/200)-0.002 -> 0.05335 | Y31: =D31+K31/200 -> 0.0023 | Z31: =E31+L31/200 -> 0.0046 | AA31: =F31+M31/200 -> 0.0032 | AB31: =G31+N31/200 -> 0.0076
A32: USDCAD | B32: 2W | C32: =[1]USDCAD!$B17 -> 0.0485 | D32: =[1]USDCAD!$F17 -> 0.0003 | E32: =[1]USDCAD!$E17 -> 0.0007 | F32: =[1]USDCAD!$D17 -> 0.0014 | G32: =[1]USDCAD!$C17 -> 0.0043 | I32: 2W | J32: =[2]G7!$C16 -> 0.73 | K32: 0.2 | L32: 0.4 | M32: 0.2 | N32: 0.4 | P32: 2W | Q32: =(C32-J32/200)-0.002 -> 0.04285 | R32: =D32-K32/200 -> -0.0007 | S32: =E32-L32/200 -> -0.0013 | T32: =F32-M32/200 -> 0.0004 | U32: =G32-N32/200 -> 0.0023 | W32: 2W | X32: =(C32+J32/200)-0.002 -> 0.05015 | Y32: =D32+K32/200 -> 0.0013 | Z32: =E32+L32/200 -> 0.0027 | AA32: =F32+M32/200 -> 0.0024 | AB32: =G32+N32/200 -> 0.0063
A33: USDCAD | B33: 1M | C33: =[1]USDCAD!$B18 -> 0.0464 | D33: =[1]USDCAD!$F18 -> -0.0003 | E33: =[1]USDCAD!$E18 -> -0.0004 | F33: =[1]USDCAD!$D18 -> 0.0012 | G33: =[1]USDCAD!$C18 -> 0.004 | I33: 1M | J33: =[2]G7!$C17 -> 0.44 | K33: 0.2 | L33: 0.4 | M33: 0.2 | N33: 0.4 | P33: 1M | Q33: =(C33-J33/200)-0.002 -> 0.0422 | R33: =D33-K33/200 -> -0.0013 | S33: =E33-L33/200 -> -0.0024 | T33: =F33-M33/200 -> 0.0002 | U33: =G33-N33/200 -> 0.002 | W33: 1M | X33: =(C33+J33/200)-0.002 -> 0.0466 | Y33: =D33+K33/200 -> 0.0007 | Z33: =E33+L33/200 -> 0.0016 | AA33: =F33+M33/200 -> 0.0022 | AB33: =G33+N33/200 -> 0.006
A34: USDCAD | B34: 2M | C34: =[1]USDCAD!$B19 -> 0.0463 | D34: =[1]USDCAD!$F19 -> -0.0004 | E34: =[1]USDCAD!$E19 -> -0.0006 | F34: =[1]USDCAD!$D19 -> 0.0014 | G34: =[1]USDCAD!$C19 -> 0.0045 | I34: 2M | J34: =[2]G7!$C18 -> 0.41 | K34: 0.2 | L34: 0.4 | M34: 0.2 | N34: 0.4 | P34: 2M | Q34: =(C34-J34/200)-0.002 -> 0.04225 | R34: =D34-K34/200 -> -0.0014 | S34: =E34-L34/200 -> -0.0026 | T34: =F34-M34/200 -> 0.0004 | U34: =G34-N34/200 -> 0.0025 | W34: 2M | X34: =(C34+J34/200)-0.002 -> 0.04635 | Y34: =D34+K34/200 -> 0.0006 | Z34: =E34+L34/200 -> 0.0014 | AA34: =F34+M34/200 -> 0.0024 | AB34: =G34+N34/200 -> 0.0065
A35: USDCAD | B35: 3M | C35: =[1]USDCAD!$B20 -> 0.0465 | D35: =[1]USDCAD!$F20 -> -0.0004 | E35: =[1]USDCAD!$E20 -> -0.0007 | F35: =[1]USDCAD!$D20 -> 0.0015 | G35: =[1]USDCAD!$C20 -> 0.005 | I35: 3M | J35: =[2]G7!$C19 -> 0.4 | K35: 0.2 | L35: 0.4 | M35: 0.2 | N35: 0.4 | P35: 3M | Q35: =(C35-J35/200)-0.002 -> 0.0425 | R35: =D35-K35/200 -> -0.0014 | S35: =E35-L35/200 -> -0.0027 | T35: =F35-M35/200 -> 0.0005 | U35: =G35-N35/200 -> 0.003 | W35: 3M | X35: =(C35+J35/200)-0.002 -> 0.0465 | Y35: =D35+K35/200 -> 0.0006 | Z35: =E35+L35/200 -> 0.0013 | AA35: =F35+M35/200 -> 0.0025 | AB35: =G35+N35/200 -> 0.007
A36: USDCAD | B36: 6M | C36: =[1]USDCAD!$B21 -> 0.0476 | D36: =[1]USDCAD!$F21 -> 0.0002 | E36: =[1]USDCAD!$E21 -> 0.0005 | F36: =[1]USDCAD!$D21 -> 0.0018 | G36: =[1]USDCAD!$C21 -> 0.006 | I36: 6M | J36: =[2]G7!$C20 -> 0.36 | K36: 0.2 | L36: 0.4 | M36: 0.2 | N36: 0.4 | P36: 6M | Q36: =(C36-J36/200)-0.002 -> 0.0438 | R36: =D36-K36/200 -> -0.0008 | S36: =E36-L36/200 -> -0.0015 | T36: =F36-M36/200 -> 0.0008 | U36: =G36-N36/200 -> 0.004 | W36: 6M | X36: =(C36+J36/200)-0.002 -> 0.0474 | Y36: =D36+K36/200 -> 0.0012 | Z36: =E36+L36/200 -> 0.0025 | AA36: =F36+M36/200 -> 0.0028 | AB36: =G36+N36/200 -> 0.008
A37: USDCAD | B37: 9M | C37: =[1]USDCAD!$B22 -> 0.0496 | D37: =[1]USDCAD!$F22 -> 0.0002 | E37: =[1]USDCAD!$E22 -> 0.0006 | F37: =[1]USDCAD!$D22 -> 0.002 | G37: =[1]USDCAD!$C22 -> 0.0069 | I37: 9M | J37: =[2]G7!$C21 -> 0.36 | K37: 0.2 | L37: 0.4 | M37: 0.2 | N37: 0.4 | P37: 9M | Q37: =(C37-J37/200)-0.002 -> 0.0458 | R37: =D37-K37/200 -> -0.0008 | S37: =E37-L37/200 -> -0.0014 | T37: =F37-M37/200 -> 0.001 | U37: =G37-N37/200 -> 0.0049 | W37: 9M | X37: =(C37+J37/200)-0.002 -> 0.0494 | Y37: =D37+K37/200 -> 0.0012 | Z37: =E37+L37/200 -> 0.0026 | AA37: =F37+M37/200 -> 0.003 | AB37: =G37+N37/200 -> 0.0089
A38: USDCAD | B38: 1Y | C38: =[1]USDCAD!$B23 -> 0.0517 | D38: =[1]USDCAD!$F23 -> 0.0002 | E38: =[1]USDCAD!$E23 -> 0.0008 | F38: =[1]USDCAD!$D23 -> 0.0022 | G38: =[1]USDCAD!$C23 -> 0.0078 | I38: 1Y | J38: =[2]G7!$C22 -> 0.35 | K38: 0.2 | L38: 0.4 | M38: 0.2 | N38: 0.4 | P38: 1Y | Q38: =(C38-J38/200)-0.002 -> 0.04795 | R38: =D38-K38/200 -> -0.0008 | S38: =E38-L38/200 -> -0.0012 | T38: =F38-M38/200 -> 0.0012 | U38: =G38-N38/200 -> 0.0058 | W38: 1Y | X38: =(C38+J38/200)-0.002 -> 0.05145 | Y38: =D38+K38/200 -> 0.0012 | Z38: =E38+L38/200 -> 0.0028 | AA38: =F38+M38/200 -> 0.0032 | AB38: =G38+N38/200 -> 0.0098
A39: USDCAD | B39: 2Y | C39: =[1]USDCAD!$B24 -> 0.054 | D39: =[1]USDCAD!$F24 -> 0.0003 | E39: =[1]USDCAD!$E24 -> 0.0011 | F39: =[1]USDCAD!$D24 -> 0.0025 | G39: =[1]USDCAD!$C24 -> 0.0093 | I39: 2Y | J39: =[2]G7!$C23 -> 0.38 | K39: 0.2 | L39: 0.4 | M39: 0.2 | N39: 0.4 | P39: 2Y | Q39: =(C39-J39/200)-0.002 -> 0.0501 | R39: =D39-K39/200 -> -0.0007 | S39: =E39-L39/200 -> -0.0009 | T39: =F39-M39/200 -> 0.0015 | U39: =G39-N39/200 -> 0.0073 | W39: 2Y | X39: =(C39+J39/200)-0.002 -> 0.0539 | Y39: =D39+K39/200 -> 0.0013 | Z39: =E39+L39/200 -> 0.0031 | AA39: =F39+M39/200 -> 0.0035 | AB39: =G39+N39/200 -> 0.0113
A40: USDCAD | B40: 3Y | C40: =[1]USDCAD!$B25 -> 0.0563 | D40: =[1]USDCAD!$F25 -> 0.001 | E40: =[1]USDCAD!$E25 -> 0.0025 | F40: =[1]USDCAD!$D25 -> 0.0025 | G40: =[1]USDCAD!$C25 -> 0.0094 | I40: 3Y | J40: =[2]G7!$C24 -> 0.37 | K40: 0.2 | L40: 0.4 | M40: 0.2 | N40: 0.4 | P40: 3Y | Q40: =(C40-J40/200)-0.002 -> 0.05245 | R40: =D40-K40/200 -> 0 | S40: =E40-L40/200 -> 0.0005 | T40: =F40-M40/200 -> 0.0015 | U40: =G40-N40/200 -> 0.0074 | W40: 3Y | X40: =(C40+J40/200)-0.002 -> 0.05615 | Y40: =D40+K40/200 -> 0.002 | Z40: =E40+L40/200 -> 0.0045 | AA40: =F40+M40/200 -> 0.0035 | AB40: =G40+N40/200 -> 0.0114
A43: Ccy Pair | B43: Mid | C43: ATM | D43: 25D RR | E43: 10D RR | F43: 25D BF | G43: 10D BF | I43: Spread | J43: ATM | K43: 25D RR | L43: 10D RR | M43: 25D BF | N43: 10D BF | P43: BID | Q43: ATM | R43: 25D RR | S43: 10D RR | T43: 25D BF | U43: 10D BF | W43: OFFER | X43: ATM | Y43: 25D RR | Z43: 10D RR | AA43: 25D BF | AB43: 10D BF
A44: CADHKD | B44: ON | C44: =[1]CADHKD!$B15 -> 0.0551 | D44: =[1]CADHKD!$F15 -> -0.0004 | E44: =[1]CADHKD!$E15 -> -0.0007 | F44: =[1]CADHKD!$D15 -> 0.0011 | G44: =[1]CADHKD!$C15 -> 0.0041 | I44: ON | J44: =[2]G7!$D14 -> 9.43 | K44: 0.9 | L44: 1.8 | M44: 1.3 | N44: 2.6 | P44: ON | Q44: =(C44-J44/200)-0.002 -> 0.00595 | R44: =D44-K44/200 -> -0.0049 | S44: =E44-L44/200 -> -0.0097 | T44: =F44-M44/200 -> -0.0054 | U44: =G44-N44/200 -> -0.0089 | W44: ON | X44: =(C44+J44/200)-0.002 -> 0.10025 | Y44: =D44+K44/200 -> 0.0041 | Z44: =E44+L44/200 -> 0.0083 | AA44: =F44+M44/200 -> 0.0076 | AB44: =G44+N44/200 -> 0.0171
A45: CADHKD | B45: 1W | C45: =[1]CADHKD!$B16 -> 0.0484 | D45: =[1]CADHKD!$F16 -> -0.0002 | E45: =[1]CADHKD!$E16 -> -0.0004 | F45: =[1]CADHKD!$D16 -> 0.001 | G45: =[1]CADHKD!$C16 -> 0.0038 | I45: 1W | J45: =[2]G7!$D15 -> 4.04 | K45: 0.4 | L45: 0.8 | M45: 0.4 | N45: 0.8 | P45: 1W | Q45: =(C45-J45/200)-0.002 -> 0.0262 | R45: =D45-K45/200 -> -0.0022 | S45: =E45-L45/200 -> -0.0044 | T45: =F45-M45/200 -> -0.001 | U45: =G45-N45/200 -> -0.0002 | W45: 1W | X45: =(C45+J45/200)-0.002 -> 0.0666 | Y45: =D45+K45/200 -> 0.0018 | Z45: =E45+L45/200 -> 0.0036 | AA45: =F45+M45/200 -> 0.003 | AB45: =G45+N45/200 -> 0.0078
A46: CADHKD | B46: 2W | C46: =[1]CADHKD!$B17 -> 0.0453 | D46: =[1]CADHKD!$F17 -> 0.0001 | E46: =[1]CADHKD!$E17 -> 0.0002 | F46: =[1]CADHKD!$D17 -> 0.0011 | G46: =[1]CADHKD!$C17 -> 0.004 | I46: 2W | J46: =[2]G7!$D16 -> 2.39 | K46: 0.2 | L46: 0.4 | M46: 0.2 | N46: 0.4 | P46: 2W | Q46: =(C46-J46/200)-0.002 -> 0.03135 | R46: =D46-K46/200 -> -0.0009 | S46: =E46-L46/200 -> -0.0018 | T46: =F46-M46/200 -> 0.0001 | U46: =G46-N46/200 -> 0.002 | W46: 2W | X46: =(C46+J46/200)-0.002 -> 0.05525 | Y46: =D46+K46/200 -> 0.0011 | Z46: =E46+L46/200 -> 0.0022 | AA46: =F46+M46/200 -> 0.0021 | AB46: =G46+N46/200 -> 0.006
...

Sheet G7 Output
A1: AUDUSD | O1: Bloomberg | P1: DCAP Formula | R1: Bloomberg | S1: DCAP Formula | U1: Bloomberg | V1: DCAP Formula | X1: Bloomberg | Y1: DCAP Formula | AA1: Bloomberg | AB1: DCAP Formula
A2: Bid | B2: ATM Vol | C2: RR25 | D2: RR10 | E2: Fly25 | F2: Fly10 | H2: Ask | I2: ATM Vol | J2: RR25 | K2: RR10 | L2: Fly25 | M2: Fly10 | O2: ATM | P2: Bid | Q2: Ask | R2: RR25 | S2: Bid | T2: Ask | U2: RR10 | V2: Bid | W2: Ask | X2: Fly25 | Y2: Bid | Z2: Ask | AA2: Fly10 | AB2: Bid | AC2: Ask
A3: ON | B3: ='G7 Input'!Q2 -> 0.0584 | C3: ='G7 Input'!R2 -> -0.0093 | D3: ='G7 Input'!S2 -> -0.0184 | E3: ='G7 Input'!T2 -> -0.005 | F3: ='G7 Input'!U2 -> -0.0086 | H3: ON | I3: ='G7 Input'!X2 -> 0.0664 | J3: ='G7 Input'!Y2 -> 0.0027 | K3: ='G7 Input'!Z2 -> 0.0056 | L3: ='G7 Input'!AA2 -> 0.007 | M3: ='G7 Input'!AB2 -> 0.0154 | O3: ADUSV1D | P3: =_xll.PLContribFull(B3*100,"BID",O3,"Slot46","TICKER",3,,"Valid") -> 5.840 (12:14:42.765166) | Q3: =_xll.PLContribFull(I3*100,"ASK",O3,"Slot46","TICKER",3,,"Valid") -> 6.640 (12:14:42.767165) | R3: ADUSRR1D | S3: =_xll.PLContribFull(C3*100,"BID",R3,"Slot46","TICKER",3,,"Valid") -> -0.930 (12:14:42.747168) | T3: =_xll.PLContribFull(J3*100,"ASK",R3,"Slot46","TICKER",3,,"Valid") -> 0.270 (12:14:42.770167) | U3: ADUSRX1D | V3: =_xll.PLContribFull(D3*100,"BID",U3,"Slot46","TICKER",3,,"Valid") -> -1.840 (12:14:42.745167) | W3: =_xll.PLContribFull(K3*100,"ASK",U3,"Slot46","TICKER",3,,"Valid") -> 0.560 (12:14:42.766166) | X3: ADUSB1D | Y3: =_xll.PLContribFull(E3*100,"BID",X3,"Slot46","TICKER",3,,"Valid") -> -0.500 (12:14:42.762166) | Z3: =_xll.PLContribFull(L3*100,"ASK",X3,"Slot46","TICKER",3,,"Valid") -> 0.700 (12:14:42.742167) | AA3: ADUSBX1D | AB3: =_xll.PLContribFull(F3*100,"BID",AA3,"Slot46","TICKER",3,,"Valid") -> -0.860 (12:14:42.773167) | AC3: =_xll.PLContribFull(M3*100,"ASK",AA3,"Slot46","TICKER",3,,"Valid") -> 1.540 (12:14:42.760167)
A4: 1W | B4: ='G7 Input'!Q3 -> 0.0571 | C4: ='G7 Input'!R3 -> -0.0061 | D4: ='G7 Input'!S3 -> -0.0131 | E4: ='G7 Input'!T3 -> -0.0013 | F4: ='G7 Input'!U3 -> -0.0007 | H4: 1W | I4: ='G7 Input'!X3 -> 0.0639 | J4: ='G7 Input'!Y3 -> -0.0011 | K4: ='G7 Input'!Z3 -> -0.0031 | L4: ='G7 Input'!AA3 -> 0.0037 | M4: ='G7 Input'!AB3 -> 0.0093 | O4: ADUSV1W | P4: =_xll.PLContribFull(B4*100,"BID",O4,"Slot46","TICKER",3,,"Valid") -> 5.710 (12:14:42.762166) | Q4: =_xll.PLContribFull(I4*100,"ASK",O4,"Slot46","TICKER",3,,"Valid") -> 6.390 (12:14:42.760167) | R4: ADUSRR1W | S4: =_xll.PLContribFull(C4*100,"BID",R4,"Slot46","TICKER",3,,"Valid") -> -0.610 (12:14:42.778167) | T4: =_xll.PLContribFull(J4*100,"ASK",R4,"Slot46","TICKER",3,,"Valid") -> -0.110 (12:14:42.767165) | U4: ADUSRX1W | V4: =_xll.PLContribFull(D4*100,"BID",U4,"Slot46","TICKER",3,,"Valid") -> -1.310 (12:14:42.766166) | W4: =_xll.PLContribFull(K4*100,"ASK",U4,"Slot46","TICKER",3,,"Valid") -> -0.310 (12:14:42.764166) | X4: ADUSB1W | Y4: =_xll.PLContribFull(E4*100,"BID",X4,"Slot46","TICKER",3,,"Valid") -> -0.130 (12:14:42.753167) | Z4: =_xll.PLContribFull(L4*100,"ASK",X4,"Slot46","TICKER",3,,"Valid") -> 0.370 (12:14:42.762166) | AA4: ADUSBX1W | AB4: =_xll.PLContribFull(F4*100,"BID",AA4,"Slot46","TICKER",3,,"Valid") -> -0.070 (12:14:42.751168) | AC4: =_xll.PLContribFull(M4*100,"ASK",AA4,"Slot46","TICKER",3,,"Valid") -> 0.930 (12:14:42.771168)
A5: 2W | B5: ='G7 Input'!Q4 -> 0.06225 | C5: ='G7 Input'!R4 -> -0.0056 | D5: ='G7 Input'!S4 -> -0.012 | E5: ='G7 Input'!T4 -> -0.0002 | F5: ='G7 Input'!U4 -> 0.0017 | H5: 2W | I5: ='G7 Input'!X4 -> 0.06755 | J5: ='G7 Input'!Y4 -> -0.0026 | K5: ='G7 Input'!Z4 -> -0.006 | L5: ='G7 Input'!AA4 -> 0.0028 | M5: ='G7 Input'!AB4 -> 0.0077 | O5: ADUSV2W | P5: =_xll.PLContribFull(B5*100,"BID",O5,"Slot46","TICKER",3,,"Valid") -> 6.225 (12:14:42.770167) | Q5: =_xll.PLContribFull(I5*100,"ASK",O5,"Slot46","TICKER",3,,"Valid") -> 6.755 (12:14:42.761166) | R5: ADUSRR2W | S5: =_xll.PLContribFull(C5*100,"BID",R5,"Slot46","TICKER",3,,"Valid") -> -0.560 (12:14:42.769168) | T5: =_xll.PLContribFull(J5*100,"ASK",R5,"Slot46","TICKER",3,,"Valid") -> -0.260 (12:14:42.774166) | U5: ADUSRX2W | V5: =_xll.PLContribFull(D5*100,"BID",U5,"Slot46","TICKER",3,,"Valid") -> -1.200 (12:14:42.776167) | W5: =_xll.PLContribFull(K5*100,"ASK",U5,"Slot46","TICKER",3,,"Valid") -> -0.600 (12:14:42.763166) | X5: ADUSB2W | Y5: =_xll.PLContribFull(E5*100,"BID",X5,"Slot46","TICKER",3,,"Valid") -> -0.020 (12:14:42.764166) | Z5: =_xll.PLContribFull(L5*100,"ASK",X5,"Slot46","TICKER",3,,"Valid") -> 0.280 (12:14:42.762166) | AA5: ADUSBX2W | AB5: =_xll.PLContribFull(F5*100,"BID",AA5,"Slot46","TICKER",3,,"Valid") -> 0.170 (12:14:42.761166) | AC5: =_xll.PLContribFull(M5*100,"ASK",AA5,"Slot46","TICKER",3,,"Valid") -> 0.770 (12:14:42.761166)
A6: 1M | B6: ='G7 Input'!Q5 -> 0.0663 | C6: ='G7 Input'!R5 -> -0.0059 | D6: ='G7 Input'!S5 -> -0.012 | E6: ='G7 Input'!T5 -> 0.0004 | F6: ='G7 Input'!U5 -> 0.0031 | H6: 1M | I6: ='G7 Input'!X5 -> 0.0697 | J6: ='G7 Input'!Y5 -> -0.0039 | K6: ='G7 Input'!Z5 -> -0.008 | L6: ='G7 Input'!AA5 -> 0.0024 | M6: ='G7 Input'!AB5 -> 0.0071 | O6: ADUSV1M | P6: =_xll.PLContribFull(B6*100,"BID",O6,"Slot46","TICKER",3,,"Valid") -> 6.630 (12:14:42.770167) | Q6: =_xll.PLContribFull(I6*100,"ASK",O6,"Slot46","TICKER",3,,"Valid") -> 6.970 (12:14:42.770167) | R6: ADUSVRR | S6: =_xll.PLContribFull(C6*100,"BID",R6,"Slot46","TICKER",3,,"Valid") -> -0.590 (12:14:42.761166) | T6: =_xll.PLContribFull(J6*100,"ASK",R6,"Slot46","TICKER",3,,"Valid") -> -0.390 (12:14:42.774166) | U6: ADUSRX1M | V6: =_xll.PLContribFull(D6*100,"BID",U6,"Slot46","TICKER",3,,"Valid") -> -1.200 (12:14:42.776167) | W6: =_xll.PLContribFull(K6*100,"ASK",U6,"Slot46","TICKER",3,,"Valid") -> -0.800 (12:14:42.763166) | X6: ADUSB1M | Y6: =_xll.PLContribFull(E6*100,"BID",X6,"Slot46","TICKER",3,,"Valid") -> 0.040 (12:14:42.753167) | Z6: =_xll.PLContribFull(L6*100,"ASK",X6,"Slot46","TICKER",3,,"Valid") -> 0.240 (12:14:42.770167) | AA6: ADUSBX1M | AB6: =_xll.PLContribFull(F6*100,"BID",AA6,"Slot46","TICKER",3,,"Valid") -> 0.310 (12:14:42.755167) | AC6: =_xll.PLContribFull(M6*100,"ASK",AA6,"Slot46","TICKER",3,,"Valid") -> 0.710 (12:14:42.777166)
A7: 2M | B7: ='G7 Input'!Q6 -> 0.0687 | C7: ='G7 Input'!R6 -> -0.0066 | D7: ='G7 Input'!S6 -> -0.0137 | E7: ='G7 Input'!T6 -> 0.0007 | F7: ='G7 Input'!U6 -> 0.004 | H7: 2M | I7: ='G7 Input'!X6 -> 0.0721 | J7: ='G7 Input'!Y6 -> -0.0046 | K7: ='G7 Input'!Z6 -> -0.0097 | L7: ='G7 Input'!AA6 -> 0.0027 | M7: ='G7 Input'!AB6 -> 0.008 | O7: ADUSV2M | P7: =_xll.PLContribFull(B7*100,"BID",O7,"Slot46","TICKER",3,,"Valid") -> 6.870 (12:14:42.759166) | Q7: =_xll.PLContribFull(I7*100,"ASK",O7,"Slot46","TICKER",3,,"Valid") -> 7.210 (12:14:42.768166) | R7: ADUSRR2M | S7: =_xll.PLContribFull(C7*100,"BID",R7,"Slot46","TICKER",3,,"Valid") -> -0.660 (12:14:42.764166) | T7: =_xll.PLContribFull(J7*100,"ASK",R7,"Slot46","TICKER",3,,"Valid") -> -0.460 (12:14:42.767165) | U7: ADUSRX2M | V7: =_xll.PLContribFull(D7*100,"BID",U7,"Slot46","TICKER",3,,"Valid") -> -1.370 (12:14:42.770167) | W7: =_xll.PLContribFull(K7*100,"ASK",U7,"Slot46","TICKER",3,,"Valid") -> -0.970 (12:14:42.767165) | X7: ADUSB2M | Y7: =_xll.PLContribFull(E7*100,"BID",X7,"Slot46","TICKER",3,,"Valid") -> 0.070 (12:14:42.762166) | Z7: =_xll.PLContribFull(L7*100,"ASK",X7,"Slot46","TICKER",3,,"Valid") -> 0.270 (12:14:42.763166) | AA7: ADUSBX2M | AB7: =_xll.PLContribFull(F7*100,"BID",AA7,"Slot46","TICKER",3,,"Valid") -> 0.400 (12:14:42.762166) | AC7: =_xll.PLContribFull(M7*100,"ASK",AA7,"Slot46","TICKER",3,,"Valid") -> 0.800 (12:14:42.756167)
A8: 3M | B8: ='G7 Input'!Q7 -> 0.0703 | C8: ='G7 Input'!R7 -> -0.0072 | D8: ='G7 Input'!S7 -> -0.0152 | E8: ='G7 Input'!T7 -> 0.001 | F8: ='G7 Input'!U7 -> 0.0049 | H8: 3M | I8: ='G7 Input'!X7 -> 0.0737 | J8: ='G7 Input'!Y7 -> -0.0052 | K8: ='G7 Input'!Z7 -> -0.0112 | L8: ='G7 Input'!AA7 -> 0.003 | M8: ='G7 Input'!AB7 -> 0.0089 | O8: ADUSV3M | P8: =_xll.PLContribFull(B8*100,"BID",O8,"Slot46","TICKER",3,,"Valid") -> 7.030 (12:14:42.768166) | Q8: =_xll.PLContribFull(I8*100,"ASK",O8,"Slot46","TICKER",3,,"Valid") -> 7.370 (12:14:42.763166) | R8: ADUSRR3M | S8: =_xll.PLContribFull(C8*100,"BID",R8,"Slot46","TICKER",3,,"Valid") -> -0.720 (12:14:42.767165) | T8: =_xll.PLContribFull(J8*100,"ASK",R8,"Slot46","TICKER",3,,"Valid") -> -0.520 (12:14:42.770167) | U8: ADUSRX3M | V8: =_xll.PLContribFull(D8*100,"BID",U8,"Slot46","TICKER",3,,"Valid") -> -1.520 (12:14:42.763166) | W8: =_xll.PLContribFull(K8*100,"ASK",U8,"Slot46","TICKER",3,,"Valid") -> -1.120 (12:14:42.764166) | X8: ADUSB3M | Y8: =_xll.PLContribFull(E8*100,"BID",X8,"Slot46","TICKER",3,,"Valid") -> 0.100 (12:14:42.778167) | Z8: =_xll.PLContribFull(L8*100,"ASK",X8,"Slot46","TICKER",3,,"Valid") -> 0.300 (12:14:42.753167) | AA8: ADUSBX3M | AB8: =_xll.PLContribFull(F8*100,"BID",AA8,"Slot46","TICKER",3,,"Valid") -> 0.490 (12:14:42.749167) | AC8: =_xll.PLContribFull(M8*100,"ASK",AA8,"Slot46","TICKER",3,,"Valid") -> 0.890 (12:14:42.769168)
A9: 6M | B9: ='G7 Input'!Q8 -> 0.07385 | C9: ='G7 Input'!R8 -> -0.0085 | D9: ='G7 Input'!S8 -> -0.0179 | E9: ='G7 Input'!T8 -> 0.0012 | F9: ='G7 Input'!U8 -> 0.0057 | H9: 6M | I9: ='G7 Input'!X8 -> 0.07715 | J9: ='G7 Input'!Y8 -> -0.0065 | K9: ='G7 Input'!Z8 -> -0.0139 | L9: ='G7 Input'!AA8 -> 0.0032 | M9: ='G7 Input'!AB8 -> 0.0097 | O9: ADUSV6M | P9: =_xll.PLContribFull(B9*100,"BID",O9,"Slot46","TICKER",3,,"Valid") -> 7.385 (12:14:42.759166) | Q9: =_xll.PLContribFull(I9*100,"ASK",O9,"Slot46","TICKER",3,,"Valid") -> 7.715 (12:14:42.768166) | R9: ADUSRR6M | S9: =_xll.PLContribFull(C9*100,"BID",R9,"Slot46","TICKER",3,,"Valid") -> -0.850 (12:14:42.771168) | T9: =_xll.PLContribFull(J9*100,"ASK",R9,"Slot46","TICKER",3,,"Valid") -> -0.650 (12:14:42.774166) | U9: ADUSRX6M | V9: =_xll.PLContribFull(D9*100,"BID",U9,"Slot46","TICKER",3,,"Valid") -> -1.790 (12:14:42.742167) | W9: =_xll.PLContribFull(K9*100,"ASK",U9,"Slot46","TICKER",3,,"Valid") -> -1.390 (12:14:42.773167) | X9: ADUSB6M | Y9: =_xll.PLContribFull(E9*100,"BID",X9,"Slot46","TICKER",3,,"Valid") -> 0.120 (12:14:42.770167) | Z9: =_xll.PLContribFull(L9*100,"ASK",X9,"Slot46","TICKER",3,,"Valid") -> 0.320 (12:14:42.767165) | AA9: ADUSBX6M | AB9: =_xll.PLContribFull(F9*100,"BID",AA9,"Slot46","TICKER",3,,"Valid") -> 0.570 (12:14:42.750168) | AC9: =_xll.PLContribFull(M9*100,"ASK",AA9,"Slot46","TICKER",3,,"Valid") -> 0.970 (12:14:42.774166)
A10: 9M | B10: ='G7 Input'!Q9 -> 0.07745 | C10: ='G7 Input'!R9 -> -0.0095 | D10: ='G7 Input'!S9 -> -0.0201 | E10: ='G7 Input'!T9 -> 0.0015 | F10: ='G7 Input'!U9 -> 0.007 | H10: 9M | I10: ='G7 Input'!X9 -> 0.08075 | J10: ='G7 Input'!Y9 -> -0.0075 | K10: ='G7 Input'!Z9 -> -0.0161 | L10: ='G7 Input'!AA9 -> 0.0035 | M10: ='G7 Input'!AB9 -> 0.011 | O10: ADUSV9M | P10: =_xll.PLContribFull(B10*100,"BID",O10,"Slot46","TICKER",3,,"Valid") -> 7.745 (12:14:42.764166) | Q10: =_xll.PLContribFull(I10*100,"ASK",O10,"Slot46","TICKER",3,,"Valid") -> 8.075 (12:14:42.767165) | R10: ADUSRR9M | S10: =_xll.PLContribFull(C10*100,"BID",R10,"Slot46","TICKER",3,,"Valid") -> -0.950 (12:14:42.742167) | T10: =_xll.PLContribFull(J10*100,"ASK",R10,"Slot46","TICKER",3,,"Valid") -> -0.750 (12:14:42.764166) | U10: ADUSRX9M | V10: =_xll.PLContribFull(D10*100,"BID",U10,"Slot46","TICKER",3,,"Valid") -> -2.010 (12:14:42.778167) | W10: =_xll.PLContribFull(K10*100,"ASK",U10,"Slot46","TICKER",3,,"Valid") -> -1.610 (12:14:42.745167) | X10: ADUSB9M | Y10: =_xll.PLContribFull(E10*100,"BID",X10,"Slot46","TICKER",3,,"Valid") -> 0.150 (12:14:42.740168) | Z10: =_xll.PLContribFull(L10*100,"ASK",X10,"Slot46","TICKER",3,,"Valid") -> 0.350 (12:14:42.764166) | AA10: ADUSBX9M | AB10: =_xll.PLContribFull(F10*100,"BID",AA10,"Slot46","TICKER",3,,"Valid") -> 0.700 (12:14:42.764166) | AC10: =_xll.PLContribFull(M10*100,"ASK",AA10,"Slot46","TICKER",3,,"Valid") -> 1.100 (12:14:42.770167)
A11: 1Y | B11: ='G7 Input'!Q10 -> 0.08045 | C11: ='G7 Input'!R10 -> -0.0105 | D11: ='G7 Input'!S10 -> -0.0222 | E11: ='G7 Input'!T10 -> 0.0019 | F11: ='G7 Input'!U10 -> 0.0083 | H11: 1Y | I11: ='G7 Input'!X10 -> 0.08395 | J11: ='G7 Input'!Y10 -> -0.0085 | K11: ='G7 Input'!Z10 -> -0.0182 | L11: ='G7 Input'!AA10 -> 0.0039 | M11: ='G7 Input'!AB10 -> 0.0123 | O11: ADUSV1Y | P11: =_xll.PLContribFull(B11*100,"BID",O11,"Slot46","TICKER",3,,"Valid") -> 8.045 (12:14:42.774166) | Q11: =_xll.PLContribFull(I11*100,"ASK",O11,"Slot46","TICKER",3,,"Valid") -> 8.395 (12:14:42.766166) | R11: ADUSRR1Y | S11: =_xll.PLContribFull(C11*100,"BID",R11,"Slot46","TICKER",3,,"Valid") -> -1.050 (12:14:42.774166) | T11: =_xll.PLContribFull(J11*100,"ASK",R11,"Slot46","TICKER",3,,"Valid") -> -0.850 (12:14:42.769168) | U11: ADUSRX1Y | V11: =_xll.PLContribFull(D11*100,"BID",U11,"Slot46","TICKER",3,,"Valid") -> -2.220 (12:14:42.758167) | W11: =_xll.PLContribFull(K11*100,"ASK",U11,"Slot46","TICKER",3,,"Valid") -> -1.820 (12:14:42.742167) | X11: ADUSB1Y | Y11: =_xll.PLContribFull(E11*100,"BID",X11,"Slot46","TICKER",3,,"Valid") -> 0.190 (12:14:42.762166) | Z11: =_xll.PLContribFull(L11*100,"ASK",X11,"Slot46","TICKER",3,,"Valid") -> 0.390 (12:14:42.776167) | AA11: ADUSBX1Y | AB11: =_xll.PLContribFull(F11*100,"BID",AA11,"Slot46","TICKER",3,,"Valid") -> 0.830 (12:14:42.759166) | AC11: =_xll.PLContribFull(M11*100,"ASK",AA11,"Slot46","TICKER",3,,"Valid") -> 1.230 (12:14:42.765166)
A12: 2Y | B12: ='G7 Input'!Q11 -> 0.0845 | C12: ='G7 Input'!R11 -> -0.0127 | D12: ='G7 Input'!S11 -> -0.0263 | E12: ='G7 Input'!T11 -> 0.0029 | F12: ='G7 Input'!U11 -> 0.0112 | H12: 2Y | I12: ='G7 Input'!X11 -> 0.0885 | J12: ='G7 Input'!Y11 -> -0.0107 | K12: ='G7 Input'!Z11 -> -0.0223 | L12: ='G7 Input'!AA11 -> 0.0049 | M12: ='G7 Input'!AB11 -> 0.0152 | O12: ADUSV2Y | P12: =_xll.PLContribFull(B12*100,"BID",O12,"Slot46","TICKER",3,,"Valid") -> 8.450 (12:14:42.769168) | Q12: =_xll.PLContribFull(I12*100,"ASK",O12,"Slot46","TICKER",3,,"Valid") -> 8.850 (12:14:42.777166) | R12: ADUSRR2Y | S12: =_xll.PLContribFull(C12*100,"BID",R12,"Slot46","TICKER",3,,"Valid") -> -1.270 (12:14:42.765166) | T12: =_xll.PLContribFull(J12*100,"ASK",R12,"Slot46","TICKER",3,,"Valid") -> -1.070 (12:14:42.772166) | U12: ADUSRX2Y | V12: =_xll.PLContribFull(D12*100,"BID",U12,"Slot46","TICKER",3,,"Valid") -> -2.630 (12:14:42.773167) | W12: =_xll.PLContribFull(K12*100,"ASK",U12,"Slot46","TICKER",3,,"Valid") -> -2.230 (12:14:42.771168) | X12: ADUSB2Y | Y12: =_xll.PLContribFull(E12*100,"BID",X12,"Slot46","TICKER",3,,"Valid") -> 0.290 (12:14:42.763166) | Z12: =_xll.PLContribFull(L12*100,"ASK",X12,"Slot46","TICKER",3,,"Valid") -> 0.490 (12:14:42.771168) | AA12: ADUSBX2Y | AB12: =_xll.PLContribFull(F12*100,"BID",AA12,"Slot46","TICKER",3,,"Valid") -> 1.120 (12:14:42.764166) | AC12: =_xll.PLContribFull(M12*100,"ASK",AA12,"Slot46","TICKER",3,,"Valid") -> 1.520 (12:14:42.754169)
A13: 3Y | B13: ='G7 Input'!Q12 -> 0.08575 | C13: ='G7 Input'!R12 -> -0.013 | D13: ='G7 Input'!S12 -> -0.0268 | E13: ='G7 Input'!T12 -> 0.0028 | F13: ='G7 Input'!U12 -> 0.0113 | H13: 3Y | I13: ='G7 Input'!X12 -> 0.09045 | J13: ='G7 Input'!Y12 -> -0.011 | K13: ='G7 Input'!Z12 -> -0.0228 | L13: ='G7 Input'!AA12 -> 0.0048 | M13: ='G7 Input'!AB12 -> 0.0153 | O13: ADUSV3Y | P13: =_xll.PLContribFull(B13*100,"BID",O13,"Slot46","TICKER",3,,"Valid") -> 8.575 (12:14:42.772166) | Q13: =_xll.PLContribFull(I13*100,"ASK",O13,"Slot46","TICKER",3,,"Valid") -> 9.045 (12:14:42.778167) | R13: ADUSRR3Y | S13: =_xll.PLContribFull(C13*100,"BID",R13,"Slot46","TICKER",3,,"Valid") -> -1.300 (12:14:42.769168) | T13: =_xll.PLContribFull(J13*100,"ASK",R13,"Slot46","TICKER",3,,"Valid") -> -1.100 (12:14:42.751168) | U13: ADUSRX3Y | V13: =_xll.PLContribFull(D13*100,"BID",U13,"Slot46","TICKER",3,,"Valid") -> -2.680 (12:14:42.768166) | W13: =_xll.PLContribFull(K13*100,"ASK",U13,"Slot46","TICKER",3,,"Valid") -> -2.280 (12:14:42.744167) | X13: ADUSB3Y | Y13: =_xll.PLContribFull(E13*100,"BID",X13,"Slot46","TICKER",3,,"Valid") -> 0.280 (12:14:42.753167) | Z13: =_xll.PLContribFull(L13*100,"ASK",X13,"Slot46","TICKER",3,,"Valid") -> 0.480 (12:14:42.775167) | AA13: ADUSBX3Y | AB13: =_xll.PLContribFull(F13*100,"BID",AA13,"Slot46","TICKER",3,,"Valid") -> 1.130 (12:14:42.769168) | AC13: =_xll.PLContribFull(M13*100,"ASK",AA13,"Slot46","TICKER",3,,"Valid") -> 1.530 (12:14:42.777166)
A16: AUDHKD | O16: Bloomberg | P16: DCAP Formula | R16: Bloomberg | S16: DCAP Formula | U16: Bloomberg | V16: DCAP Formula | X16: Bloomberg | Y16: DCAP Formula | AA16: Bloomberg | AB16: DCAP Formula
A17: Bid | B17: ATM Vol | C17: RR25 | D17: RR10 | E17: Fly25 | F17: Fly10 | H17: Ask | I17: ATM Vol | J17: RR25 | K17: RR10 | L17: Fly25 | M17: Fly10 | O17: ATM | P17: Bid | Q17: Ask | R17: RR25 | S17: Bid | T17: Ask | U17: RR10 | V17: Bid | W17: Ask | X17: Fly25 | Y17: Bid | Z17: Ask | AA17: Fly10 | AB17: Bid | AC17: Ask
A18: ON | B18: ='G7 Input'!Q16 -> 0.0456 | C18: ='G7 Input'!R16 -> -0.0099 | D18: ='G7 Input'!S16 -> -0.0197 | E18: ='G7 Input'!T16 -> -0.0048 | F18: ='G7 Input'!U16 -> -0.0077 | H18: ON | I18: ='G7 Input'!X16 -> 0.0766 | J18: ='G7 Input'!Y16 -> 0.0021 | K18: ='G7 Input'!Z16 -> 0.0043 | L18: ='G7 Input'!AA16 -> 0.0072 | M18: ='G7 Input'!AB16 -> 0.0163 | O18: ADHDV1D | P18: =_xll.PLContribFull(B18*100,"BID",O18,"Slot46","TICKER",3,,"Valid") -> 4.560 (12:14:42.765166) | Q18: =_xll.PLContribFull(I18*100,"ASK",O18,"Slot46","TICKER",3,,"Valid") -> 7.660 (12:14:42.766166) | R18: ADHDRR1D | S18: =_xll.PLContribFull(C18*100,"BID",R18,"Slot46","TICKER",3,,"Valid") -> -0.990 (12:14:42.767165) | T18: =_xll.PLContribFull(J18*100,"ASK",R18,"Slot46","TICKER",3,,"Valid") -> 0.210 (12:14:42.767165) | U18: ADHDRX1D | V18: =_xll.PLContribFull(D18*100,"BID",U18,"Slot46","TICKER",3,,"Valid") -> -1.970 (12:14:42.771168) | W18: =_xll.PLContribFull(K18*100,"ASK",U18,"Slot46","TICKER",3,,"Valid") -> 0.430 (12:14:42.769168) | X18: ADHDB1D | Y18: =_xll.PLContribFull(E18*100,"BID",X18,"Slot46","TICKER",3,,"Valid") -> -0.480 (12:14:42.767165) | Z18: =_xll.PLContribFull(L18*100,"ASK",X18,"Slot46","TICKER",3,,"Valid") -> 0.720 (12:14:42.754169) | AA18: ADHDBX1D | AB18: =_xll.PLContribFull(F18*100,"BID",AA18,"Slot46","TICKER",3,,"Valid") -> -0.770 (12:14:42.773167) | AC18: =_xll.PLContribFull(M18*100,"ASK",AA18,"Slot46","TICKER",3,,"Valid") -> 1.630 (12:14:42.765166)
A19: 1W | B19: ='G7 Input'!Q17 -> 0.04925 | C19: ='G7 Input'!R17 -> -0.0064 | D19: ='G7 Input'!S17 -> -0.0125 | E19: ='G7 Input'!T17 -> -0.0014 | F19: ='G7 Input'!U17 -> -0.0008 | H19: 1W | I19: ='G7 Input'!X17 -> 0.07035 | J19: ='G7 Input'!Y17 -> -0.0014 | K19: ='G7 Input'!Z17 -> -0.0025 | L19: ='G7 Input'!AA17 -> 0.0036 | M19: ='G7 Input'!AB17 -> 0.0092 | O19: ADHDV1W | P19: =_xll.PLContribFull(B19*100,"BID",O19,"Slot46","TICKER",3,,"Valid") -> 4.925 (12:14:42.761166) | Q19: =_xll.PLContribFull(I19*100,"ASK",O19,"Slot46","TICKER",3,,"Valid") -> 7.035 (12:14:42.774166) | R19: ADHDRR1W | S19: =_xll.PLContribFull(C19*100,"BID",R19,"Slot46","TICKER",3,,"Valid") -> -0.640 (12:14:42.747168) | T19: =_xll.PLContribFull(J19*100,"ASK",R19,"Slot46","TICKER",3,,"Valid") -> -0.140 (12:14:42.759166) | U19: ADHDRX1W | V19: =_xll.PLContribFull(D19*100,"BID",U19,"Slot46","TICKER",3,,"Valid") -> -1.250 (12:14:42.756167) | W19: =_xll.PLContribFull(K19*100,"ASK",U19,"Slot46","TICKER",3,,"Valid") -> -0.250 (12:14:42.760167) | X19: ADHDB1W | Y19: =_xll.PLContribFull(E19*100,"BID",X19,"Slot46","TICKER",3,,"Valid") -> -0.140 (12:14:42.772166) | Z19: =_xll.PLContribFull(L19*100,"ASK",X19,"Slot46","TICKER",3,,"Valid") -> 0.360 (12:14:42.747168) | AA19: ADHDBX1W | AB19: =_xll.PLContribFull(F19*100,"BID",AA19,"Slot46","TICKER",3,,"Valid") -> -0.080 (12:14:42.764166) | AC19: =_xll.PLContribFull(M19*100,"ASK",AA19,"Slot46","TICKER",3,,"Valid") -> 0.920 (12:14:42.763166)
A20: 2W | B20: ='G7 Input'!Q18 -> 0.05815 | C20: ='G7 Input'!R18 -> -0.0062 | D20: ='G7 Input'!S18 -> -0.0121 | E20: ='G7 Input'!T18 -> -0.0002 | F20: ='G7 Input'!U18 -> 0.0018 | H20: 2W | I20: ='G7 Input'!X18 -> 0.07325 | J20: ='G7 Input'!Y18 -> -0.0032 | K20: ='G7 Input'!Z18 -> -0.0061 | L20: ='G7 Input'!AA18 -> 0.0028 | M20: ='G7 Input'!AB18 -> 0.0078 | O20: ADHDV2W | P20: =_xll.PLContribFull(B20*100,"BID",O20,"Slot46","TICKER",3,,"Valid") -> 5.815 (12:14:42.763166) | Q20: =_xll.PLContribFull(I20*100,"ASK",O20,"Slot46","TICKER",3,,"Valid") -> 7.325 (12:14:42.762166) | R20: ADHDRR2W | S20: =_xll.PLContribFull(C20*100,"BID",R20,"Slot46","TICKER",3,,"Valid") -> -0.620 (12:14:42.764166) | T20: =_xll.PLContribFull(J20*100,"ASK",R20,"Slot46","TICKER",3,,"Valid") -> -0.320 (12:14:42.764166) | U20: ADHDRX2W | V20: =_xll.PLContribFull(D20*100,"BID",U20,"Slot46","TICKER",3,,"Valid") -> -1.210 (12:14:42.769168) | W20: =_xll.PLContribFull(K20*100,"ASK",U20,"Slot46","TICKER",3,,"Valid") -> -0.610 (12:14:42.748167) | X20: ADHDB2W | Y20: =_xll.PLContribFull(E20*100,"BID",X20,"Slot46","TICKER",3,,"Valid") -> -0.020 (12:14:42.741170) | Z20: =_xll.PLContribFull(L20*100,"ASK",X20,"Slot46","TICKER",3,,"Valid") -> 0.280 (12:14:42.777166) | AA20: ADHDBX2W | AB20: =_xll.PLContribFull(F20*100,"BID",AA20,"Slot46","TICKER",3,,"Valid") -> 0.180 (12:14:42.769168) | AC20: =_xll.PLContribFull(M20*100,"ASK",AA20,"Slot46","TICKER",3,,"Valid") -> 0.780 (12:14:42.770167)
A21: 1M | B21: ='G7 Input'!Q19 -> 0.06365 | C21: ='G7 Input'!R19 -> -0.006 | D21: ='G7 Input'!S19 -> -0.0117 | E21: ='G7 Input'!T19 -> 0.0004 | F21: ='G7 Input'!U19 -> 0.003 | H21: 1M | I21: ='G7 Input'!X19 -> 0.07115 | J21: ='G7 Input'!Y19 -> -0.004 | K21: ='G7 Input'!Z19 -> -0.0077 | L21: ='G7 Input'!AA19 -> 0.0024 | M21: ='G7 Input'!AB19 -> 0.007 | O21: ADHDV1M | P21: =_xll.PLContribFull(B21*100,"BID",O21,"Slot46","TICKER",3,,"Valid") -> 6.365 (12:14:42.766166) | Q21: =_xll.PLContribFull(I21*100,"ASK",O21,"Slot46","TICKER",3,,"Valid") -> 7.115 (12:14:42.762166) | R21: ADHDVRR | S21: =_xll.PLContribFull(C21*100,"BID",R21,"Slot46","TICKER",3,,"Valid") -> -0.600 (12:14:42.768166) | T21: =_xll.PLContribFull(J21*100,"ASK",R21,"Slot46","TICKER",3,,"Valid") -> -0.400 (12:14:42.746167) | U21: ADHDRX1M | V21: =_xll.PLContribFull(D21*100,"BID",U21,"Slot46","TICKER",3,,"Valid") -> -1.170 (12:14:42.761166) | W21: =_xll.PLContribFull(K21*100,"ASK",U21,"Slot46","TICKER",3,,"Valid") -> -0.770 (12:14:42.762166) | X21: ADHDB1M | Y21: =_xll.PLContribFull(E21*100,"BID",X21,"Slot46","TICKER",3,,"Valid") -> 0.040 (12:14:42.742167) | Z21: =_xll.PLContribFull(L21*100,"ASK",X21,"Slot46","TICKER",3,,"Valid") -> 0.240 (12:14:42.765166) | AA21: ADHDBX1M | AB21: =_xll.PLContribFull(F21*100,"BID",AA21,"Slot46","TICKER",3,,"Valid") -> 0.300 (12:14:42.774166) | AC21: =_xll.PLContribFull(M21*100,"ASK",AA21,"Slot46","TICKER",3,,"Valid") -> 0.700 (12:14:42.777166)
A22: 2M | B22: ='G7 Input'!Q20 -> 0.0666 | C22: ='G7 Input'!R20 -> -0.0068 | D22: ='G7 Input'!S20 -> -0.0133 | E22: ='G7 Input'!T20 -> 0.0006 | F22: ='G7 Input'!U20 -> 0.004 | H22: 2M | I22: ='G7 Input'!X20 -> 0.074 | J22: ='G7 Input'!Y20 -> -0.0048 | K22: ='G7 Input'!Z20 -> -0.0093 | L22: ='G7 Input'!AA20 -> 0.0026 | M22: ='G7 Input'!AB20 -> 0.008 | O22: ADHDV2M | P22: =_xll.PLContribFull(B22*100,"BID",O22,"Slot46","TICKER",3,,"Valid") -> 6.660 (12:14:42.775167) | Q22: =_xll.PLContribFull(I22*100,"ASK",O22,"Slot46","TICKER",3,,"Valid") -> 7.400 (12:14:42.764166) | R22: ADHDRR2M | S22: =_xll.PLContribFull(C22*100,"BID",R22,"Slot46","TICKER",3,,"Valid") -> -0.680 (12:14:42.775167) | T22: =_xll.PLContribFull(J22*100,"ASK",R22,"Slot46","TICKER",3,,"Valid") -> -0.480 (12:14:42.770167) | U22: ADHDRX2M | V22: =_xll.PLContribFull(D22*100,"BID",U22,"Slot46","TICKER",3,,"Valid") -> -1.330 (12:14:42.772166) | W22: =_xll.PLContribFull(K22*100,"ASK",U22,"Slot46","TICKER",3,,"Valid") -> -0.930 (12:14:42.748167) | X22: ADHDB2M | Y22: =_xll.PLContribFull(E22*100,"BID",X22,"Slot46","TICKER",3,,"Valid") -> 0.060 (12:14:42.767165) | Z22: =_xll.PLContribFull(L22*100,"ASK",X22,"Slot46","TICKER",3,,"Valid") -> 0.260 (12:14:42.742167) | AA22: ADHDBX2M | AB22: =_xll.PLContribFull(F22*100,"BID",AA22,"Slot46","TICKER",3,,"Valid") -> 0.400 (12:14:42.769168) | AC22: =_xll.PLContribFull(M22*100,"ASK",AA22,"Slot46","TICKER",3,,"Valid") -> 0.800 (12:14:42.750168)
A23: 3M | B23: ='G7 Input'!Q21 -> 0.06815 | C23: ='G7 Input'!R21 -> -0.0075 | D23: ='G7 Input'!S21 -> -0.0146 | E23: ='G7 Input'!T21 -> 0.0008 | F23: ='G7 Input'!U21 -> 0.0048 | H23: 3M | I23: ='G7 Input'!X21 -> 0.07565 | J23: ='G7 Input'!Y21 -> -0.0055 | K23: ='G7 Input'!Z21 -> -0.0106 | L23: ='G7 Input'!AA21 -> 0.0028 | M23: ='G7 Input'!AB21 -> 0.0088 | O23: ADHDV3M | P23: =_xll.PLContribFull(B23*100,"BID",O23,"Slot46","TICKER",3,,"Valid") -> 6.815 (12:14:42.778167) | Q23: =_xll.PLContribFull(I23*100,"ASK",O23,"Slot46","TICKER",3,,"Valid") -> 7.565 (12:14:42.762166) | R23: ADHDRR3M | S23: =_xll.PLContribFull(C23*100,"BID",R23,"Slot46","TICKER",3,,"Valid") -> -0.750 (12:14:42.752166) | T23: =_xll.PLContribFull(J23*100,"ASK",R23,"Slot46","TICKER",3,,"Valid") -> -0.550 (12:14:42.760167) | U23: ADHDRX3M | V23: =_xll.PLContribFull(D23*100,"BID",U23,"Slot46","TICKER",3,,"Valid") -> -1.460 (12:14:42.766166) | W23: =_xll.PLContribFull(K23*100,"ASK",U23,"Slot46","TICKER",3,,"Valid") -> -1.060 (12:14:42.771168) | X23: ADHDB3M | Y23: =_xll.PLContribFull(E23*100,"BID",X23,"Slot46","TICKER",3,,"Valid") -> 0.080 (12:14:42.763166) | Z23: =_xll.PLContribFull(L23*100,"ASK",X23,"Slot46","TICKER",3,,"Valid") -> 0.280 (12:14:42.744167) | AA23: ADHDBX3M | AB23: =_xll.PLContribFull(F23*100,"BID",AA23,"Slot46","TICKER",3,,"Valid") -> 0.480 (12:14:42.773167) | AC23: =_xll.PLContribFull(M23*100,"ASK",AA23,"Slot46","TICKER",3,,"Valid") -> 0.880 (12:14:42.743167)
A24: 6M | B24: ='G7 Input'!Q22 -> 0.0719 | C24: ='G7 Input'!R22 -> -0.0087 | D24: ='G7 Input'!S22 -> -0.0169 | E24: ='G7 Input'!T22 -> 0.0009 | F24: ='G7 Input'!U22 -> 0.0056 | H24: 6M | I24: ='G7 Input'!X22 -> 0.0789 | J24: ='G7 Input'!Y22 -> -0.0067 | K24: ='G7 Input'!Z22 -> -0.0129 | L24: ='G7 Input'!AA22 -> 0.0029 | M24: ='G7 Input'!AB22 -> 0.0096 | O24: ADHDV6M | P24: =_xll.PLContribFull(B24*100,"BID",O24,"Slot46","TICKER",3,,"Valid") -> 7.190 (12:14:42.779168) | Q24: =_xll.PLContribFull(I24*100,"ASK",O24,"Slot46","TICKER",3,,"Valid") -> 7.890 (12:14:42.759166) | R24: ADHDRR6M | S24: =_xll.PLContribFull(C24*100,"BID",R24,"Slot46","TICKER",3,,"Valid") -> -0.870 (12:14:42.752166) | T24: =_xll.PLContribFull(J24*100,"ASK",R24,"Slot46","TICKER",3,,"Valid") -> -0.670 (12:14:42.777166) | U24: ADHDRX6M | V24: =_xll.PLContribFull(D24*100,"BID",U24,"Slot46","TICKER",3,,"Valid") -> -1.690 (12:14:42.741170) | W24: =_xll.PLContribFull(K24*100,"ASK",U24,"Slot46","TICKER",3,,"Valid") -> -1.290 (12:14:42.763166) | X24: ADHDB6M | Y24: =_xll.PLContribFull(E24*100,"BID",X24,"Slot46","TICKER",3,,"Valid") -> 0.090 (12:14:42.770167) | Z24: =_xll.PLContribFull(L24*100,"ASK",X24,"Slot46","TICKER",3,,"Valid") -> 0.290 (12:14:42.759166) | AA24: ADHDBX6M | AB24: =_xll.PLContribFull(F24*100,"BID",AA24,"Slot46","TICKER",3,,"Valid") -> 0.560 (12:14:42.744167) | AC24: =_xll.PLContribFull(M24*100,"ASK",AA24,"Slot46","TICKER",3,,"Valid") -> 0.960 (12:14:42.770167)
A25: 9M | B25: ='G7 Input'!Q23 -> 0.0764 | C25: ='G7 Input'!R23 -> -0.0104 | D25: ='G7 Input'!S23 -> -0.02 | E25: ='G7 Input'!T23 -> 0.0013 | F25: ='G7 Input'!U23 -> 0.0074 | H25: 9M | I25: ='G7 Input'!X23 -> 0.0834 | J25: ='G7 Input'!Y23 -> -0.0084 | K25: ='G7 Input'!Z23 -> -0.016 | L25: ='G7 Input'!AA23 -> 0.0033 | M25: ='G7 Input'!AB23 -> 0.0114 | O25: ADHDV9M | P25: =_xll.PLContribFull(B25*100,"BID",O25,"Slot46","TICKER",3,,"Valid") -> 7.640 (12:14:42.765166) | Q25: =_xll.PLContribFull(I25*100,"ASK",O25,"Slot46","TICKER",3,,"Valid") -> 8.340 (12:14:42.770167) | R25: ADHDRR9M | S25: =_xll.PLContribFull(C25*100,"BID",R25,"Slot46","TICKER",3,,"Valid") -> -1.040 (12:14:42.776167) | T25: =_xll.PLContribFull(J25*100,"ASK",R25,"Slot46","TICKER",3,,"Valid") -> -0.840 (12:14:42.754169) | U25: ADHDRX9M | V25: =_xll.PLContribFull(D25*100,"BID",U25,"Slot46","TICKER",3,,"Valid") -> -2.000 (12:14:42.777166) | W25: =_xll.PLContribFull(K25*100,"ASK",U25,"Slot46","TICKER",3,,"Valid") -> -1.600 (12:14:42.746167) | X25: ADHDB9M | Y25: =_xll.PLContribFull(E25*100,"BID",X25,"Slot46","TICKER",3,,"Valid") -> 0.130 (12:14:42.767165) | Z25: =_xll.PLContribFull(L25*100,"ASK",X25,"Slot46","TICKER",3,,"Valid") -> 0.330 (12:14:42.777166) | AA25: ADHDBX9M | AB25: =_xll.PLContribFull(F25*100,"BID",AA25,"Slot46","TICKER",3,,"Valid") -> 0.740 (12:14:42.764166) | AC25: =_xll.PLContribFull(M25*100,"ASK",AA25,"Slot46","TICKER",3,,"Valid") -> 1.140 (12:14:42.754169)
A26: 1Y | B26: ='G7 Input'!Q24 -> 0.07885 | C26: ='G7 Input'!R24 -> -0.0112 | D26: ='G7 Input'!S24 -> -0.0216 | E26: ='G7 Input'!T24 -> 0.0015 | F26: ='G7 Input'!U24 -> 0.0083 | H26: 1Y | I26: ='G7 Input'!X24 -> 0.08615 | J26: ='G7 Input'!Y24 -> -0.0092 | K26: ='G7 Input'!Z24 -> -0.0176 | L26: ='G7 Input'!AA24 -> 0.0035 | M26: ='G7 Input'!AB24 -> 0.0123 | O26: ADHDV1Y | P26: =_xll.PLContribFull(B26*100,"BID",O26,"Slot46","TICKER",3,,"Valid") -> 7.885 (12:14:42.760167) | Q26: =_xll.PLContribFull(I26*100,"ASK",O26,"Slot46","TICKER",3,,"Valid") -> 8.615 (12:14:42.759166) | R26: ADHDRR1Y | S26: =_xll.PLContribFull(C26*100,"BID",R26,"Slot46","TICKER",3,,"Valid") -> -1.120 (12:14:42.751168) | T26: =_xll.PLContribFull(J26*100,"ASK",R26,"Slot46","TICKER",3,,"Valid") -> -0.920 (12:14:42.763166) | U26: ADHDRX1Y | V26: =_xll.PLContribFull(D26*100,"BID",U26,"Slot46","TICKER",3,,"Valid") -> -2.160 (12:14:42.776167) | W26: =_xll.PLContribFull(K26*100,"ASK",U26,"Slot46","TICKER",3,,"Valid") -> -1.760 (12:14:42.774166) | X26: ADHDB1Y | Y26: =_xll.PLContribFull(E26*100,"BID",X26,"Slot46","TICKER",3,,"Valid") -> 0.150 (12:14:42.773167) | Z26: =_xll.PLContribFull(L26*100,"ASK",X26,"Slot46","TICKER",3,,"Valid") -> 0.350 (12:14:42.759166) | AA26: ADHDBX1Y | AB26: =_xll.PLContribFull(F26*100,"BID",AA26,"Slot46","TICKER",3,,"Valid") -> 0.830 (12:14:42.772166) | AC26: =_xll.PLContribFull(M26*100,"ASK",AA26,"Slot46","TICKER",3,,"Valid") -> 1.230 (12:14:42.752166)
A27: 2Y | B27: ='G7 Input'!Q25 -> 0.08205 | C27: ='G7 Input'!R25 -> -0.0134 | D27: ='G7 Input'!S25 -> -0.0255 | E27: ='G7 Input'!T25 -> 0.0019 | F27: ='G7 Input'!U25 -> 0.0104 | H27: 2Y | I27: ='G7 Input'!X25 -> 0.09215 | J27: ='G7 Input'!Y25 -> -0.0114 | K27: ='G7 Input'!Z25 -> -0.0215 | L27: ='G7 Input'!AA25 -> 0.0039 | M27: ='G7 Input'!AB25 -> 0.0144 | O27: ADHDV2Y | P27: =_xll.PLContribFull(B27*100,"BID",O27,"Slot46","TICKER",3,,"Valid") -> 8.205 (12:14:42.771168) | Q27: =_xll.PLContribFull(I27*100,"ASK",O27,"Slot46","TICKER",3,,"Valid") -> 9.215 (12:14:42.759166) | R27: ADHDRR2Y | S27: =_xll.PLContribFull(C27*100,"BID",R27,"Slot46","TICKER",3,,"Valid") -> -1.340 (12:14:42.776167) | T27: =_xll.PLContribFull(J27*100,"ASK",R27,"Slot46","TICKER",3,,"Valid") -> -1.140 (12:14:42.751168) | U27: ADHDRX2Y | V27: =_xll.PLContribFull(D27*100,"BID",U27,"Slot46","TICKER",3,,"Valid") -> -2.550 (12:14:42.775167) | W27: =_xll.PLContribFull(K27*100,"ASK",U27,"Slot46","TICKER",3,,"Valid") -> -2.150 (12:14:42.774166) | X27: ADHDB2Y | Y27: =_xll.PLContribFull(E27*100,"BID",X27,"Slot46","TICKER",3,,"Valid") -> 0.190 (12:14:42.778167) | Z27: =_xll.PLContribFull(L27*100,"ASK",X27,"Slot46","TICKER",3,,"Valid") -> 0.390 (12:14:42.778167) | AA27: ADHDBX2Y | AB27: =_xll.PLContribFull(F27*100,"BID",AA27,"Slot46","TICKER",3,,"Valid") -> 1.040 (12:14:42.768166) | AC27: =_xll.PLContribFull(M27*100,"ASK",AA27,"Slot46","TICKER",3,,"Valid") -> 1.440 (12:14:42.767165)
A28: 3Y | B28: ='G7 Input'!Q26 -> 0.08315 | C28: ='G7 Input'!R26 -> -0.0141 | D28: ='G7 Input'!S26 -> -0.0265 | E28: ='G7 Input'!T26 -> 0.0017 | F28: ='G7 Input'!U26 -> 0.0103 | H28: 3Y | I28: ='G7 Input'!X26 -> 0.09605 | J28: ='G7 Input'!Y26 -> -0.0121 | K28: ='G7 Input'!Z26 -> -0.0225 | L28: ='G7 Input'!AA26 -> 0.0037 | M28: ='G7 Input'!AB26 -> 0.0143 | O28: ADHDV3Y | P28: =_xll.PLContribFull(B28*100,"BID",O28,"Slot46","TICKER",3,,"Valid") -> 8.315 (12:14:42.775167) | Q28: =_xll.PLContribFull(I28*100,"ASK",O28,"Slot46","TICKER",3,,"Valid") -> 9.605 (12:14:42.764166) | R28: ADHDRR3Y | S28: =_xll.PLContribFull(C28*100,"BID",R28,"Slot46","TICKER",3,,"Valid") -> -1.410 (12:14:42.765166) | T28: =_xll.PLContribFull(J28*100,"ASK",R28,"Slot46","TICKER",3,,"Valid") -> -1.210 (12:14:42.773167) | U28: ADHDRX3Y | V28: =_xll.PLContribFull(D28*100,"BID",U28,"Slot46","TICKER",3,,"Valid") -> -2.650 (12:14:42.771168) | W28: =_xll.PLContribFull(K28*100,"ASK",U28,"Slot46","TICKER",3,,"Valid") -> -2.250 (12:14:42.766166) | X28: ADHDB3Y | Y28: =_xll.PLContribFull(E28*100,"BID",X28,"Slot46","TICKER",3,,"Valid") -> 0.170 (12:14:42.775167) | Z28: =_xll.PLContribFull(L28*100,"ASK",X28,"Slot46","TICKER",3,,"Valid") -> 0.370 (12:14:42.768166) | AA28: ADHDBX3Y | AB28: =_xll.PLContribFull(F28*100,"BID",AA28,"Slot46","TICKER",3,,"Valid") -> 1.030 (12:14:42.765166) | AC28: =_xll.PLContribFull(M28*100,"ASK",AA28,"Slot46","TICKER",3,,"Valid") -> 1.430 (12:14:42.744167)
A31: USDCAD | O31: Bloomberg | P31: DCAP Formula | R31: Bloomberg | S31: DCAP Formula | U31: Bloomberg | V31: DCAP Formula | X31: Bloomberg | Y31: DCAP Formula | AA31: Bloomberg | AB31: DCAP Formula
A32: Bid | B32: ATM Vol | C32: RR25 | D32: RR10 | E32: Fly25 | F32: Fly10 | H32: Ask | I32: ATM Vol | J32: RR25 | K32: RR10 | L32: Fly25 | M32: Fly10 | O32: ATM | P32: Bid | Q32: Ask | R32: RR25 | S32: Bid | T32: Ask | U32: RR10 | V32: Bid | W32: Ask | X32: Fly25 | Y32: Bid | Z32: Ask | AA32: Fly10 | AB32: Bid | AC32: Ask
A33: ON | B33: ='G7 Input'!Q30 -> 0.0384 | C33: ='G7 Input'!R30 -> -0.0042 | D33: ='G7 Input'!S30 -> -0.0084 | E33: ='G7 Input'!T30 -> -0.0056 | F33: ='G7 Input'!U30 -> -0.0099 | H33: ON | I33: ='G7 Input'!X30 -> 0.0648 | J33: ='G7 Input'!Y30 -> 0.0048 | K33: ='G7 Input'!Z30 -> 0.0096 | L33: ='G7 Input'!AA30 -> 0.0074 | M33: ='G7 Input'!AB30 -> 0.0161 | O33: USCDV1D | P33: =_xll.PLContribFull(B33*100,"BID",O33,"Slot46","TICKER",3,,"Valid") -> 3.840 (12:14:42.776167) | Q33: =_xll.PLContribFull(I33*100,"ASK",O33,"Slot46","TICKER",3,,"Valid") -> 6.480 (12:14:42.763166) | R33: USCDRR1D | S33: =_xll.PLContribFull(C33*100,"BID",R33,"Slot46","TICKER",3,,"Valid") -> -0.420 (12:14:42.778167) | T33: =_xll.PLContribFull(J33*100,"ASK",R33,"Slot46","TICKER",3,,"Valid") -> 0.480 (12:14:42.776167) | U33: USCDRX1D | V33: =_xll.PLContribFull(D33*100,"BID",U33,"Slot46","TICKER",3,,"Valid") -> -0.840 (12:14:42.745167) | W33: =_xll.PLContribFull(K33*100,"ASK",U33,"Slot46","TICKER",3,,"Valid") -> 0.960 (12:14:42.763166) | X33: USCDB1D | Y33: =_xll.PLContribFull(E33*100,"BID",X33,"Slot46","TICKER",3,,"Valid") -> -0.560 (12:14:42.749167) | Z33: =_xll.PLContribFull(L33*100,"ASK",X33,"Slot46","TICKER",3,,"Valid") -> 0.740 (12:14:42.771168) | AA33: USCDBX1D | AB33: =_xll.PLContribFull(F33*100,"BID",AA33,"Slot46","TICKER",3,,"Valid") -> -0.990 (12:14:42.775167) | AC33: =_xll.PLContribFull(M33*100,"ASK",AA33,"Slot46","TICKER",3,,"Valid") -> 1.610 (12:14:42.747168)
A34: 1W | B34: ='G7 Input'!Q31 -> 0.04105 | C34: ='G7 Input'!R31 -> -0.0017 | D34: ='G7 Input'!S31 -> -0.0034 | E34: ='G7 Input'!T31 -> -0.0008 | F34: ='G7 Input'!U31 -> -0.0004 | H34: 1W | I34: ='G7 Input'!X31 -> 0.05335 | J34: ='G7 Input'!Y31 -> 0.0023 | K34: ='G7 Input'!Z31 -> 0.0046 | L34: ='G7 Input'!AA31 -> 0.0032 | M34: ='G7 Input'!AB31 -> 0.0076 | O34: USCDV1W | P34: =_xll.PLContribFull(B34*100,"BID",O34,"Slot46","TICKER",3,,"Valid") -> 4.105 (12:14:42.759166) | Q34: =_xll.PLContribFull(I34*100,"ASK",O34,"Slot46","TICKER",3,,"Valid") -> 5.335 (12:14:42.771168) | R34: USCDRR1W | S34: =_xll.PLContribFull(C34*100,"BID",R34,"Slot46","TICKER",3,,"Valid") -> -0.170 (12:14:42.747168) | T34: =_xll.PLContribFull(J34*100,"ASK",R34,"Slot46","TICKER",3,,"Valid") -> 0.230 (12:14:42.769168) | U34: USCDRX1W | V34: =_xll.PLContribFull(D34*100,"BID",U34,"Slot46","TICKER",3,,"Valid") -> -0.340 (12:14:42.768166) | W34: =_xll.PLContribFull(K34*100,"ASK",U34,"Slot46","TICKER",3,,"Valid") -> 0.460 (12:14:42.774166) | X34: USCDB1W | Y34: =_xll.PLContribFull(E34*100,"BID",X34,"Slot46","TICKER",3,,"Valid") -> -0.080 (12:14:42.749167) | Z34: =_xll.PLContribFull(L34*100,"ASK",X34,"Slot46","TICKER",3,,"Valid") -> 0.320 (12:14:42.759166) | AA34: USCDBX1W | AB34: =_xll.PLContribFull(F34*100,"BID",AA34,"Slot46","TICKER",3,,"Valid") -> -0.040 (12:14:42.739168) | AC34: =_xll.PLContribFull(M34*100,"ASK",AA34,"Slot46","TICKER",3,,"Valid") -> 0.760 (12:14:42.768166)
